Workbook

Sheet Sheet1
B1: GDP per capita data
N2: Annandale
B3: 2015 | C3: 2018 | D3: 2021 | N3: Arbeidslus
A4: Western Cape | C4: 87361 | D4: 81650 | N4: Brandwacht
A5: Cape Winelands | B5: 72719 | C5: 71908 | D5: 67798 | N5: Cloetesville
A6: Witzenberg | B6: 63728 | C6: 65315 | D6: 63733 | N6: Coetzenburg
A7: Drakenstein | B7: 78750 | C7: 76861 | D7: 71183 | N7: Dalsig
A8: Stellenbosch | B8: 92980 | C8: 90569 | D8: 84325 | N8: Dennesig
A9: Breede Valley | B9: 62510 | C9: 62237 | D9: 58951 | N9: De Zalze
A10: Langeberg | B10: 55714 | C10: 56009 | D10: 54374 | N10: De Novo
N11: Devon Valley
N12: Die Boord, previously Rhodes Fruit Farms
N13: Die Rant
N14: Ida's Valley
N15: Jamestown
N16: Jonkershoek
N17: Karindal
N18: Kayamandi
N19: Klapmuts
N20: Koelenhof
N21: Krigeville
N22: Kylemore
... N45: Welgevonden

Sheet pups
A1: PUP ID | B1: cluster_id | C1: Cluster Name | D1: Latitude | E1: longitude | F1: waste gen rate min | G1: waste gen rate max | H1: waste gen rate mod | I1: Distance to depot | J1: Distance to lf
A2: 0 | B2: 0 | C2: Uniepark | D2: -33.930655 | E2: 18.886916 | F2: 0.0438 | G2: 0.1096 | H2: 0.06575 | I2: 2679.127 | J2: 7316.377
A3: 1 | B3: 0 | C3: Uniepark | D3: -33.929716 | E3: 18.883511 | F3: 0.0438 | G3: 0.1096 | H3: 0.06575 | I3: 1697.148 | J3: 6742.773
A4: 2 | B4: 0 | C4: Uniepark | D4: -33.932666 | E4: 18.886877 | F4: 0.0438 | G4: 0.1096 | H4: 0.06575 | I4: 2266.078 | J4: 6903.329
A5: 3 | B5: 0 | C5: Uniepark | D5: -33.931232 | E5: 18.883822 | F5: 0.0438 | G5: 0.1096 | H5: 0.06575 | I5: 1645.222 | J5: 6690.847
A6: 4 | B6: 0 | C6: Uniepark | D6: -33.927951 | E6: 18.882126 | F6: 0.0438 | G6: 0.1096 | H6: 0.06575 | I6: 1551.655 | J6: 6597.28
A7: 5 | B7: 0 | C7: Uniepark | D7: -33.933051 | E7: 18.887937 | F7: 0.0438 | G7: 0.1096 | H7: 0.06575 | I7: 2202.575 | J7: 6839.826
A8: 6 | B8: 0 | C8: Uniepark | D8: -33.931364 | E8: 18.886148 | F8: 0.0438 | G8: 0.1096 | H8: 0.06575 | I8: 2549.797 | J8: 7187.047
A9: 7 | B9: 0 | C9: Uniepark | D9: -33.930506 | E9: 18.891216 | F9: 0.0438 | G9: 0.1096 | H9: 0.06575 | I9: 2626.205 | J9: 7263.456
A10: 8 | B10: 0 | C10: Uniepark | D10: -33.930483 | E10: 18.886414 | F10: 0.0438 | G10: 0.1096 | H10: 0.06575 | I10: 2338.279 | J10: 7383.903
A11: 9 | B11: 0 | C11: Uniepark | D11: -33.929094 | E11: 18.89087 | F11: 0.0438 | G11: 0.1096 | H11: 0.06575 | I11: 3109.167 | J11: 8167.582
A12: 10 | B12: 0 | C12: Uniepark | D12: -33.930209 | E12: 18.887019 | F12: 0.0438 | G12: 0.1096 | H12: 0.06575 | I12: 2679.127 | J12: 7316.377
A13: 11 | B13: 0 | C13: Uniepark | D13: -33.929215 | E13: 18.883699 | F13: 0.0438 | G13: 0.1096 | H13: 0.06575 | I13: 2034.811 | J13: 7080.436
... A1016: 214 | B1016: 10 | C1016: Kayamandi2 | D1016: -33.918262 | E1016: 18.847224 | F1016: 0.06575 | G1016: 0.1643 | H1016: 0.0986 | I1016: 4168.507 | J1016: 6086.048

Sheet Sheet3
A1: PUP ID | B1: cluster_id | C1: Cluster Name | D1: Latitude | E1: longitude | F1: waste gen rate min | G1: waste gen rate max | H1: waste gen rate mod | I1: Distance to depot | J1: Distance to lf | N1: PUPs from 10 clusters for validation
A2: 4 | B2: 0 | C2: Uniepark | D2: -33.927951 | E2: 18.882126 | F2: 0.0438 | G2: 0.1096 | H2: 0.06575 | I2: 1551.655 | J2: 6597.28 | M2: 0 | N2: 0 | O2: Uniepark | P2: -33.932355 | Q2: 18.891066 | R2: 0.0438 | S2: 0.1096 | T2: 0.06575 | U2: 2564.17 | V2: 7201.421
A3: 5 | B3: 0 | C3: Uniepark | D3: -33.933051 | E3: 18.887937 | F3: 0.0438 | G3: 0.1096 | H3: 0.06575 | I3: 2202.575 | J3: 6839.826 | M3: 1 | N3: 1 | O3: Simonswyk | P3: -33.927268 | Q3: 18.875582 | R3: 0.0438 | S3: 0.1096 | T3: 0.06575 | U3: 1346.044 | V3: 6391.668
A4: 6 | B4: 0 | C4: Uniepark | D4: -33.931364 | E4: 18.886148 | F4: 0.0438 | G4: 0.1096 | H4: 0.06575 | I4: 2549.797 | J4: 7187.047 | M4: 7 | N4: 2 | O4: Brandwacht | P4: -33.955496 | Q4: 18.874761 | R4: 0.0438 | S4: 0.1096 | T4: 0.06575 | U4: 4413.324 | V4: 6494.155
A5: 7 | B5: 0 | C5: Uniepark | D5: -33.930506 | E5: 18.891216 | F5: 0.0438 | G5: 0.1096 | H5: 0.06575 | I5: 2626.205 | J5: 7263.456 | M5: 1 | N5: 3 | O5: Paradyskloof | P5: -33.962914 | Q5: 18.851352 | R5: 0.0438 | S5: 0.1096 | T5: 0.06575 | U5: 5074.384 | V5: 5917.279
A6: 8 | B6: 0 | C6: Uniepark | D6: -33.930483 | E6: 18.886414 | F6: 0.0438 | G6: 0.1096 | H6: 0.06575 | I6: 2338.279 | J6: 7383.903 | M6: 19 | N6: 4 | O6: Jamestown | P6: -33.978066 | Q6: 18.852457 | R6: 0.0438 | S6: 0.1096 | T6: 0.06575 | U6: 7756.846 | V6: 8599.741
A7: 9 | B7: 0 | C7: Uniepark | D7: -33.929094 | E7: 18.89087 | F7: 0.0438 | G7: 0.1096 | H7: 0.06575 | I7: 3109.167 | J7: 8167.582 | M7: 37 | N7: 5 | O7: Welgevonden | P7: -33.899013 | Q7: 18.855863 | R7: 0.0438 | S7: 0.1096 | T7: 0.06575 | U7: 6323.742 | V7: 8241.282
A8: 10 | B8: 0 | C8: Uniepark | D8: -33.930209 | E8: 18.887019 | F8: 0.0438 | G8: 0.1096 | H8: 0.06575 | I8: 2679.127 | J8: 7316.377 | M8: 9 | N8: 6 | O8: Die Boord | P8: -33.945119 | Q8: 18.854802 | R8: 0.0438 | S8: 0.1096 | T8: 0.06575 | U8: 3220.779 | V8: 4063.673
A9: 11 | B9: 0 | C9: Uniepark | D9: -33.929215 | E9: 18.883699 | F9: 0.0438 | G9: 0.1096 | H9: 0.06575 | I9: 2034.811 | J9: 7080.436 | M9: 13 | N9: 7 | O9: Idas Valley | P9: -33.924882 | Q9: 18.885989 | R9: 0.0438 | S9: 0.1096 | T9: 0.06575 | U9: 1770.8093 | V9: 6496.7751
A10: 12 | B10: 0 | C10: Uniepark | D10: -33.932355 | E10: 18.891066 | F10: 0.0438 | G10: 0.1096 | H10: 0.06575 | I10: 2564.17 | J10: 7201.421 | M10: 58 | N10: 8 | O10: Cloetesville | P10: -33.900984 | Q10: 18.84507 | R10: 0.06575 | S10: 0.1643 | T10: 0.0986 | U10: 6055.621 | V10: 7973.162
A11: 13 | B11: 0 | C11: Uniepark | D11: -33.932765 | E11: 18.887796 | F11: 0.0438 | G11: 0.1096 | H11: 0.06575 | I11: 2335.444 | J11: 6972.695 | M11: 195 | N11: 9 | O11: Kayamandi1 | P11: -33.91945 | Q11: 18.844401 | R11: 0.06575 | S11: 0.1643 | T11: 0.0986 | U11: 4483.944 | V11: 6401.485
A12: 4 | B12: 1 | C12: Simonswyk | D12: -33.925856 | E12: 18.874465 | F12: 0.0438 | G12: 0.1096 | H12: 0.06575 | I12: 1496.225 | J12: 6326.239
A13: 5 | B13: 1 | C13: Simonswyk | D13: -33.929935 | E13: 18.87915 | F13: 0.0438 | G13: 0.1096 | H13: 0.06575 | I13: 1149.978 | J13: 6195.603 | N13: PUPs from the optimization model for validation
A14: 6 | B14: 1 | C14: Simonswyk | D14: -33.928585 | E14: 18.877707 | F14: 0.0438 | G14: 0.1096 | H14: 0.06575 | I14: 1261.372 | J14: 6306.997
A15: 7 | B15: 1 | C15: Simonswyk | D15: -33.9279 | E15: 18.881793 | F15: 0.0438 | G15: 0.1096 | H15: 0.06575 | I15: 1550.477 | J15: 6596.102 | M15: AssignedTruck_ID | N15: pupID | O15: cluster_name | P15: latitude | Q15: longitude | R15: wasteQty
A16: 8 | B16: 1 | C16: Simonswyk | D16: -33.927881 | E16: 18.877922 | F16: 0.0438 | G16: 0.1096 | H16: 0.06575 | I16: 1277.379 | J16: 6323.004 | M16: 3 | N16: 0 | O16: Uniepark | P16: -33.932355 | Q16: 18.891066 | R16: 1.3882435
A17: 9 | B17: 1 | C17: Simonswyk | D17: -33.92677 | E17: 18.881514 | F17: 0.0438 | G17: 0.1096 | H17: 0.06575 | I17: 2013.66 | J17: 7072.075 | M17: 3 | N17: 7 | O17: Uniepark | P17: -33.924882 | Q17: 18.885989 | R17: 1.0940935
A18: 10 | B18: 1 | C18: Simonswyk | D18: -33.927662 | E18: 18.87841 | F18: 0.0438 | G18: 0.1096 | H18: 0.06575 | I18: 1309.905 | J18: 6355.53 | M18: 3 | N18: 1 | O18: Uniepark | P18: -33.927268 | Q18: 18.875582 | R18: 1.7169095
A19: 11 | B19: 1 | C19: Simonswyk | D19: -33.926867 | E19: 18.875734 | F19: 0.0438 | G19: 0.1096 | H19: 0.06575 | I19: 1310.53 | J19: 6356.154 | M19: 3 | N19: 5 | O19: Uniepark | P19: -33.899013 | Q19: 18.855863 | R19: 0.98794148
A20: 12 | B20: 1 | C20: Simonswyk | D20: -33.929378 | E20: 18.881672 | F20: 0.0438 | G20: 0.1096 | H20: 0.06575 | I20: 1393.259 | J20: 6438.884 | M20: 3 | N20: 8 | O20: Uniepark | P20: -33.900984 | Q20: 18.84507 | R20: 1.0108894
A21: 13 | B21: 1 | C21: Simonswyk | D21: -33.929706 | E21: 18.879036 | F21: 0.0438 | G21: 0.1096 | H21: 0.06575 | I21: 1142.778 | J21: 6188.403 | M21: 3 | N21: 9 | O21: Uniepark | P21: -33.91945 | Q21: 18.844401 | R21: 1.0471538
A22: 8 | B22: 2 | C22: Brandwacht | D22: -33.955469 | E22: 18.865177 | F22: 0.0438 | G22: 0.1096 | H22: 0.06575 | I22: 3851.963 | J22: 5647.088 | M22: 3 | N22: 4 | O22: Uniepark | P22: -33.978066 | Q22: 18.852457 | R22: 0.93091986
A23: 9 | B23: 2 | C23: Brandwacht | D23: -33.953875 | E23: 18.87407 | F23: 0.0438 | G23: 0.1096 | H23: 0.06575 | I23: 3324.295 | J23: 6979.068 | M23: 3 | N23: 3 | O23: Uniepark | P23: -33.962914 | Q23: 18.851352 | R23: 1.0945572
A24: 10 | B24: 2 | C24: Brandwacht | D24: -33.955155 | E24: 18.866386 | F24: 0.0438 | G24: 0.1096 | H24: 0.06575 | I24: 3813.944 | J24: 5609.069 | M24: 3 | N24: 2 | O24: Uniepark | P24: -33.955496 | Q24: 18.874761 | R24: 0.98110423
A25: 11 | B25: 2 | C25: Brandwacht | D25: -33.954015 | E25: 18.859761 | F25: 0.0438 | G25: 0.1096 | H25: 0.06575 | I25: 3575.721 | J25: 5087.891 | M25: 3 | N25: 6 | O25: Uniepark | P25: -33.945119 | Q25: 18.854802 | R25: 0.92082539
A26: 12 | B26: 2 | C26: Brandwacht | D26: -33.957617 | E26: 18.874461 | F26: 0.0438 | G26: 0.1096 | H26: 0.06575 | I26: 4559.517 | J26: 6640.348
A27: 13 | B27: 2 | C27: Brandwacht | D27: -33.958087 | E27: 18.867935 | F27: 0.0438 | G27: 0.1096 | H27: 0.06575 | I27: 4411.283 | J27: 6206.408
A28: 14 | B28: 2 | C28: Brandwacht | D28: -33.957746 | E28: 18.872521 | F28: 0.0438 | G28: 0.1096 | H28: 0.06575 | I28: 4663.104 | J28: 6458.229
A29: 15 | B29: 2 | C29: Brandwacht | D29: -33.955455 | E29: 18.874536 | F29: 0.0438 | G29: 0.1096 | H29: 0.06575 | I29: 4392.476 | J29: 6473.307
A30: 16 | B30: 2 | C30: Brandwacht | D30: -33.953065 | E30: 18.858232 | F30: 0.0438 | G30: 0.1096 | H30: 0.06575 | I30: 3776.124 | J30: 4837.181
A31: 17 | B31: 2 | C31: Brandwacht | D31: -33.958569 | E31: 18.867551 | F31: 0.0438 | G31: 0.1096 | H31: 0.06575 | I31: 5345.434 | J31: 6188.329
A32: 49 | B32: 3 | C32: Paradyskloof | D32: -33.961347 | E32: 18.854739 | F32: 0.0438 | G32: 0.1096 | H32: 0.06575 | I32: 4905.13 | J32: 5748.024
A33: 50 | B33: 3 | C33: Paradyskloof | D33: -33.963058 | E33: 18.856448 | F33: 0.0438 | G33: 0.1096 | H33: 0.06575 | I33: 5199.078 | J33: 6041.973
A34: 51 | B34: 3 | C34: Paradyskloof | D34: -33.960204 | E34: 18.856498 | F34: 0.0438 | G34: 0.1096 | H34: 0.06575 | I34: 5136.613 | J34: 5979.507
A35: 52 | B35: 3 | C35: Paradyskloof | D35: -33.962206 | E35: 18.849764 | F35: 0.0438 | G35: 0.1096 | H35: 0.06575 | I35: 4899.753 | J35: 5742.648
A36: 53 | B36: 3 | C36: Paradyskloof | D36: -33.961298 | E36: 18.851054 | F36: 0.0438 | G36: 0.1096 | H36: 0.06575 | I36: 4747.636 | J36: 5590.531
A37: 54 | B37: 3 | C37: Paradyskloof | D37: -33.963533 | E37: 18.854814 | F37: 0.0438 | G37: 0.1096 | H37: 0.06575 | I37: 5737.065 | J37: 6579.96
... A101: 214 | B101: 10 | C101: Kayamandi2 | D101: -33.918262 | E101: 18.847224 | F101: 0.06575 | G101: 0.1643 | H101: 0.0986 | I101: 4168.507 | J101: 6086.048

Sheet Clusters
A1: cluster id | B1: cluster name | C1: no of households | D1: no of bins | E1: no of PUP | F1: min lat | G1: max lat | H1: min long | I1: max long | J1: avg household size | K1: tot population | L1: waste gen rate min | M1: waste gen rate max | N1: waste gen rate mode | O1: schedule | P1: schedule_code
A2: 0 | B2: Uniepark | C2: 138 | D2: 34 | E2: 13.8 | F2: -33.933845 | G2: -33.927222 | H2: 18.881763 | I2: 18.891226 | J2: 3 | K2: =C2*J2 -> 414 | L2: 0.0438 | M2: 0.1096 | N2: 0.06575 | O2: Wednesday | P2: 3
A3: 1 | B3: Simonswyk | C3: 138 | D3: 272 | E3: 13.8 | F3: -33.93057 | G3: -33.925273 | H3: 18.874173 | I3: 18.881801 | J3: 3 | K3: =C3*J3 -> 414 | L3: 0.0438 | M3: 0.1096 | N3: 0.06575 | O3: Monday | P3: 1
A4: 2 | B4: Brandwacht | C4: 182 | D4: 45 | E4: 18.2 | F4: -33.959327 | G4: -33.951727 | H4: 18.855897 | I4: 18.87478 | J4: 3 | K4: =C4*J4 -> 546 | L4: 0.0438 | M4: 0.1096 | N4: 0.06575 | O4: Thursday | P4: 4
A5: 3 | B5: Paradyskloof | C5: 593 | D5: 148.25 | E5: 59.3 | F5: -33.96815 | G5: -33.95975 | H5: 18.849458 | I5: 18.859714 | J5: 3 | K5: =C5*J5 -> 1779 | L5: 0.0438 | M5: 0.1096 | N5: 0.06575 | O5: Monday | P5: 1
A6: 4 | B6: Jamestown | C6: 601 | D6: 150 | E6: 60.1 | F6: -33.983074 | G6: -33.974782 | H6: 18.839622 | I6: 18.854728 | J6: 5 | K6: =C6*J6 -> 3005 | L6: 0.0438 | M6: 0.1096 | N6: 0.06575 | O6: Tuesday | P6: 2
A7: 5 | B7: Welgevonden | C7: 1070 | D7: 148 | E7: 71.333333 | F7: -33.903559 | G7: -33.897237 | H7: 18.846065 | I7: 18.85866 | J7: 3 | K7: =C7*J7 -> 3210 | L7: 0.0438 | M7: 0.1096 | N7: 0.06575 | O7: Wednesday | P7: 3
A8: 6 | B8: Die Boord | C8: 1089 | D8: 267 | E8: 72.6 | F8: -33.954159 | G8: -33.941557 | H8: 18.841255 | I8: 18.855331 | J8: 2 | K8: =C8*J8 -> 2178 | L8: 0.0438 | M8: 0.1096 | N8: 0.06575 | O8: Tuesday | P8: 2
A9: 7 | B9: Idas Valley | C9: 2128 | D9: 34 | E9: 106.4 | F9: -33.926305 | G9: -33.91758 | H9: 18.870832 | I9: 18.894607 | J9: 3 | K9: =C9*J9 -> 6384 | L9: 0.0438 | M9: 0.1096 | N9: 0.06575 | O9: Friday | P9: 5
A10: 8 | B10: Cloetesville | C10: 3327 | D10: 831 | E10: 166.35 | F10: -33.919988 | G10: -33.896054 | H10: 18.843478 | I10: 18.859335 | J10: 5 | K10: =C10*J10 -> 16635 | L10: 0.06575 | M10: 0.1643 | N10: 0.0986 | O10: Monday | P10: 1
A11: 9 | B11: Kayamandi1 | C11: 4282 | D11: 2141 | E11: 214.1 | F11: -33.92711 | G11: -33.91919 | H11: 18.836 | I11: 18.84489 | J11: 3 | K11: =C11*J11 -> 12846 | L11: 0.06575 | M11: 0.1643 | N11: 0.0986 | O11: Thursday | P11: 4
A12: 10 | B12: Kayamandi2 | C12: 4282 | D12: 532 | E12: 214.1 | F12: -33.91919 | G12: -33.91236 | H12: 18.84489 | I12: 18.84762 | J12: 4 | K12: =C12*J12 -> 17128 | L12: 0.06575 | M12: 0.1643 | N12: 0.0986 | O12: Friday | P12: 5

Sheet optimalRoutes
A1: AssignedTruck_ID | B1: pupID | C1: cluster_name | D1: latitude | E1: longitude | F1: wasteQty

Sheet pupsBackup
A1: PUP ID | B1: cluster_id | C1: Cluster Name | D1: Latitude | E1: longitude | F1: waste gen rate min | G1: waste gen rate max | H1: waste gen rate mod | I1: Distance to depot | J1: Distance to lf | L1: Optimal schedule structure
A2: 0 | B2: 0 | C2: Uniepark | D2: -33.930655 | E2: 18.886916 | F2: 0.0438 | G2: 0.1096 | H2: 0.06575 | I2: 2679.127 | J2: 7316.377 | L2: pupID | M2: clusterID | N2: latitude | O2: longitude | P2: wasteQty | Q2: assignedTruckID
A3: 1 | B3: 0 | C3: Uniepark | D3: -33.929716 | E3: 18.883511 | F3: 0.0438 | G3: 0.1096 | H3: 0.06575 | I3: 1697.148 | J3: 6742.773 | L3: 0 | M3: 1 | N3: -33.930655 | O3: 18.886916 | P3: 0.5 | Q3: 0
A4: 2 | B4: 0 | C4: Uniepark | D4: -33.932666 | E4: 18.886877 | F4: 0.0438 | G4: 0.1096 | H4: 0.06575 | I4: 2266.078 | J4: 6903.329 | L4: 1 | M4: 1 | N4: -33.931232 | O4: 18.883822 | P4: 0.8 | Q4: 0
A5: 3 | B5: 0 | C5: Uniepark | D5: -33.931232 | E5: 18.883822 | F5: 0.0438 | G5: 0.1096 | H5: 0.06575 | I5: 1645.222 | J5: 6690.847 | L5: 2 | M5: 1 | N5: -33.927951 | O5: 18.882126 | P5: 0.65 | Q5: 0
A6: 4 | B6: 0 | C6: Uniepark | D6: -33.927951 | E6: 18.882126 | F6: 0.0438 | G6: 0.1096 | H6: 0.06575 | I6: 1551.655 | J6: 6597.28 | L6: 3 | M6: 1 | N6: -33.933051 | O6: 18.887937 | P6: 0.41 | Q6: 0
A7: 5 | B7: 0 | C7: Uniepark | D7: -33.933051 | E7: 18.887937 | F7: 0.0438 | G7: 0.1096 | H7: 0.06575 | I7: 2202.575 | J7: 6839.826
A8: 6 | B8: 0 | C8: Uniepark | D8: -33.931364 | E8: 18.886148 | F8: 0.0438 | G8: 0.1096 | H8: 0.06575 | I8: 2549.797 | J8: 7187.047
A9: 7 | B9: 0 | C9: Uniepark | D9: -33.930506 | E9: 18.891216 | F9: 0.0438 | G9: 0.1096 | H9: 0.06575 | I9: 2626.205 | J9: 7263.456
A10: 8 | B10: 0 | C10: Uniepark | D10: -33.930483 | E10: 18.886414 | F10: 0.0438 | G10: 0.1096 | H10: 0.06575 | I10: 2338.279 | J10: 7383.903
A11: 9 | B11: 0 | C11: Uniepark | D11: -33.929094 | E11: 18.89087 | F11: 0.0438 | G11: 0.1096 | H11: 0.06575 | I11: 3109.167 | J11: 8167.582
A12: 10 | B12: 0 | C12: Uniepark | D12: -33.930209 | E12: 18.887019 | F12: 0.0438 | G12: 0.1096 | H12: 0.06575 | I12: 2679.127 | J12: 7316.377
A13: 11 | B13: 0 | C13: Uniepark | D13: -33.929215 | E13: 18.883699 | F13: 0.0438 | G13: 0.1096 | H13: 0.06575 | I13: 2034.811 | J13: 7080.436
A14: 12 | B14: 0 | C14: Uniepark | D14: -33.932355 | E14: 18.891066 | F14: 0.0438 | G14: 0.1096 | H14: 0.06575 | I14: 2564.17 | J14: 7201.421
A15: 13 | B15: 0 | C15: Uniepark | D15: -33.932765 | E15: 18.887796 | F15: 0.0438 | G15: 0.1096 | H15: 0.06575 | I15: 2335.444 | J15: 6972.695
A16: 0 | B16: 1 | C16: Simonswyk | D16: -33.928018 | E16: 18.878327 | F16: 0.0438 | G16: 0.1096 | H16: 0.06575 | I16: 1337.307 | J16: 6382.932
A17: 1 | B17: 1 | C17: Simonswyk | D17: -33.927268 | E17: 18.875582 | F17: 0.0438 | G17: 0.1096 | H17: 0.06575 | I17: 1346.044 | J17: 6391.668
A18: 2 | B18: 1 | C18: Simonswyk | D18: -33.929627 | E18: 18.878295 | F18: 0.0438 | G18: 0.1096 | H18: 0.06575 | I18: 1070.133 | J18: 6115.757
... A32: 2 | B32: 2 | C32: Brandwacht | D32: -33.957974 | E32: 18.866101 | F32: 0.0438 | G32: 0.1096 | H32: 0.06575 | I32: 5877.687 | J32: 6720.581
A33: 3 | B33: 2 | C33: Brandwacht | D33: -33.956329 | E33: 18.860006 | F33: 0.0438 | G33: 0.1096 | H33: 0.06575 | I33: 4779.98 | J33: 5622.875 | M33: =RANDBETWEEN(0,17) -> 2
A34: 4 | B34: 2 | C34: Brandwacht | D34: -33.952564 | E34: 18.856621 | F34: 0.0438 | G34: 0.1096 | H34: 0.06575 | I34: 3569.627 | J34: 4630.685
A35: 5 | B35: 2 | C35: Brandwacht | D35: -33.958416 | E35: 18.868218 | F35: 0.0438 | G35: 0.1096 | H35: 0.06575 | I35: 4437.269 | J35: 6232.394
A36: 6 | B36: 2 | C36: Brandwacht | D36: -33.95648 | E36: 18.864646 | F36: 0.0438 | G36: 0.1096 | H36: 0.06575 | I36: 5606.643 | J36: 6449.538
A37: 7 | B37: 2 | C37: Brandwacht | D37: -33.955496 | E37: 18.874761 | F37: 0.0438 | G37: 0.1096 | H37: 0.06575 | I37: 4413.324 | J37: 6494.155
A38: 8 | B38: 2 | C38: Brandwacht | D38: -33.955469 | E38: 18.865177 | F38: 0.0438 | G38: 0.1096 | H38: 0.06575 | I38: 3851.963 | J38: 5647.088
A39: 9 | B39: 2 | C39: Brandwacht | D39: -33.953875 | E39: 18.87407 | F39: 0.0438 | G39: 0.1096 | H39: 0.06575 | I39: 3324.295 | J39: 6979.068
A40: 10 | B40: 2 | C40: Brandwacht | D40: -33.955155 | E40: 18.866386 | F40: 0.0438 | G40: 0.1096 | H40: 0.06575 | I40: 3813.944 | J40: 5609.069
A41: 11 | B41: 2 | C41: Brandwacht | D41: -33.954015 | E41: 18.859761 | F41: 0.0438 | G41: 0.1096 | H41: 0.06575 | I41: 3575.721 | J41: 5087.891
A42: 12 | B42: 2 | C42: Brandwacht | D42: -33.957617 | E42: 18.874461 | F42: 0.0438 | G42: 0.1096 | H42: 0.06575 | I42: 4559.517 | J42: 6640.348
A43: 13 | B43: 2 | C43: Brandwacht | D43: -33.958087 | E43: 18.867935 | F43: 0.0438 | G43: 0.1096 | H43: 0.06575 | I43: 4411.283 | J43: 6206.408
A44: 14 | B44: 2 | C44: Brandwacht | D44: -33.957746 | E44: 18.872521 | F44: 0.0438 | G44: 0.1096 | H44: 0.06575 | I44: 4663.104 | J44: 6458.229
A45: 15 | B45: 2 | C45: Brandwacht | D45: -33.955455 | E45: 18.874536 | F45: 0.0438 | G45: 0.1096 | H45: 0.06575 | I45: 4392.476 | J45: 6473.307
... A48: 0 | B48: 3 | C48: Paradyskloof | D48: -33.964103 | E48: 18.855043 | F48: 0.0438 | G48: 0.1096 | H48: 0.06575 | I48: 5612.918 | J48: 6455.813
A49: 1 | B49: 3 | C49: Paradyskloof | D49: -33.962914 | E49: 18.851352 | F49: 0.0438 | G49: 0.1096 | H49: 0.06575 | I49: 5074.384 | J49: 5917.279 | L49: =RANDBETWEEN(0,58) -> 21
A50: 2 | B50: 3 | C50: Paradyskloof | D50: -33.966654 | E50: 18.855 | F50: 0.0438 | G50: 0.1096 | H50: 0.06575 | I50: 6112.634 | J50: 6955.529
A51: 3 | B51: 3 | C51: Paradyskloof | D51: -33.964836 | E51: 18.85169 | F51: 0.0438 | G51: 0.1096 | H51: 0.06575 | I51: 5315.581 | J51: 6158.476
A52: 4 | B52: 3 | C52: Paradyskloof | D52: -33.960675 | E52: 18.849851 | F52: 0.0438 | G52: 0.1096 | H52: 0.06575 | I52: 5030.65 | J52: 5873.544
A53: 5 | B53: 3 | C53: Paradyskloof | D53: -33.967143 | E53: 18.85615 | F53: 0.0438 | G53: 0.1096 | H53: 0.06575 | I53: 6032.185 | J53: 6875.08
A54: 6 | B54: 3 | C54: Paradyskloof | D54: -33.965003 | E54: 18.85421 | F54: 0.0438 | G54: 0.1096 | H54: 0.06575 | I54: 5464.044 | J54: 6306.939
A55: 7 | B55: 3 | C55: Paradyskloof | D55: -33.963915 | E55: 18.859704 | F55: 0.0438 | G55: 0.1096 | H55: 0.06575 | I55: 5443.907 | J55: 6286.802
...

Sheet Case study app data
C1: SMART SYSTEM WITH NEAREST DESTINATION RULE
A2: Cluster | B2: Truck ID | C2: Cum collection requests received | D2: Completed collection requests | E2: Avg collection requests queue length | F2: Total travel time (hrs) | G2: Avg filling level at disposal (m3) | H2: Total Waste Disposed | I2: Total Distance Travelled | J2: CO2 emission | K2: CVRP Distance | L2: change
A3: Unipark | B3: 1 | C3: 14 | D3: 14 | E3: 7.5 | F3: 3.4069066 | G3: 14.437983 | H3: 14.437983 | I3: 24.427175 | J3: 38.77553 | K3: 21.195711 | L3: =K3-I3 -> -3.231464
A4: Simonwyk | B4: 1 | C4: 14 | D4: 14 | E4: 7.5 | F4: 3.3107164 | G4: 14.437983 | H4: 14.437983 | I4: 18.655762 | J4: 28.37817 | K4: 17.722821 | L4: =K4-I4 -> -0.932941
A5: Brandwacht | B5: 1 | C5: 14 | D5: 14 | E5: 7.5 | F5: 3.7272152 | G5: 14.437983 | H5: 14.437983 | I5: 43.64569 | J5: 73.993574 | K5: 26.618844 | L5: =K5-I5 -> -17.026846 | M5: =CORREL(I3:I12,J3:J12) -> 0.98614417
A6: Paradyskloof | B6: 1 | C6: 14 | D6: 14 | E6: 7.5 | F6: 3.4201675 | G6: 14.437983 | H6: 14.437983 | I6: 25.22283 | J6: 39.731293 | K6: 25.18476 | L6: =K6-I6 -> -0.03807
A7: Jamestown | B7: 1 | C7: 11 | D7: 11 | E7: 6 | F7: 3 | G7: 11.43 | H7: 11.43 | I7: 18.56 | J7: 25.72 | K7: 39.588064 | L7: =K7-I7 -> 21.028064
A8: Welgevonden | B8: 1 | C8: 14 | D8: 14 | E8: 7.5 | F8: 3.5300303 | G8: 14.437983 | H8: 14.437983 | I8: 31.814599 | J8: 51.53186 | K8: 28.235207 | L8: =K8-I8 -> -3.579392
A9: Die Boord | B9: 1 | C9: 14 | D9: 14 | E9: 7.5 | F9: 3.3920927 | G9: 14.437983 | H9: 14.437983 | I9: 23.538345 | J9: 36.972799 | K9: 22.595639 | L9: =K9-I9 -> -0.942706
A10: Idas Valley | B10: 1 | C10: 14 | D10: 14 | E10: 7.5 | F10: 3.5123919 | G10: 14.437983 | H10: 14.437983 | I10: 30.756293 | J10: 50.675747 | K10: 26.529971 | L10: =K10-I10 -> -4.226322
A11: Cloetesville | B11: 2 | C11: 14 | D11: 14 | E11: 7.5 | F11: 5.5722356 | G11: 14.44 | H11: 21.651799 | I11: 52.981711 | J11: 83.041414 | K11: 43.633739 | L11: =K11-I11 -> -9.347972
A12: Khayamandi | B12: 2 | C12: 14 | D12: 14 | E12: 7.5 | F12: 5.3690975 | G12: 14.44 | H12: 21.651799 | I12: 40.793427 | J12: 57.793922 | K12: 37.633631 | L12: =K12-I12 -> -3.159796
A14: Total | F14: =SUM(F3:F12) -> 38.240854 | H14: =SUM(H3:H12) -> 155.79948 | I14: =SUM(I3:I12) -> 310.39583 | J14: =SUM(J3:J12) -> 486.61431
A16: Avg | F16: =AVERAGE(F3:F12) -> 3.8240854 | I16: =AVERAGE(I3:I12) -> 31.039583 | J16: =AVERAGE(J3:J12) -> 48.661431
A17: Std Dev | F17: =_xlfn.STDEV.S(F3:F12) -> 0.88835469 | I17: =_xlfn.STDEV.S(I3:I12) -> 11.446083 | J17: =_xlfn.STDEV.S(J3:J12) -> 18.771202
C21: SMART SYSTEM WITH OPTIMAL SOLUTION
A23: Cluster | B23: Truck ID | C23: Cum collection requests received | D23: Completed collection requests | E23: Avg collection requests queue length | F23: Total travel time (hrs) | G23: Avg filling level at disposal (m3) | H23: Total Waste Disposed | I23: Total Distance Travelled | J23: CO2 emission
A24: Unipark | B24: 1 | C24: 0 | D24: 14 | E24: 0 | F24: 3.2431689 | G24: 14.437983 | H24: 14.437983 | I24: 21.195711 | J24: 27.435017
A25: Simonwyk | B25: 1 | C25: 0 | D25: 14 | E25: 0 | F25: 3.1852874 | G25: 14.437983 | H25: 14.437983 | I25: 17.722821 | J25: 22.745979
A26: Brandwacht | B26: 1 | C26: 0 | D26: 14 | E26: 0 | F26: 3.3335544 | G26: 14.437983 | H26: 14.437983 | I26: 26.618844 | J26: 32.812999
A27: Paradyskloof | B27: 1 | C27: 0 | D27: 14 | E27: 0 | F27: 3.309653 | G27: 14.437983 | H27: 14.437983 | I27: 25.18476 | J27: 31.860826 | M27: =CORREL(I24:I33,J24:J33) -> 0.98563197
A28: Jamestown | B28: 1 | C28: 0 | D28: 11 | E28: 0 | F28: 3.2727429 | G28: 11.220343 | H28: 11.220343 | I28: 39.588064 | J28: 45.163157
A29: Welgevonden | B29: 1 | C29: 0 | D29: 14 | E29: 0 | F29: 3.3604938 | G29: 14.437983 | H29: 14.437983 | I29: 28.235207 | J29: 34.678868
A30: Die Boord | B30: 1 | C30: 0 | D30: 14 | E30: 0 | F30: 3.266501 | G30: 14.437983 | H30: 14.437983 | I30: 22.595639 | J30: 26.410447
A31: Idas Valley | B31: 1 | C31: 0 | D31: 14 | E31: 0 | F31: 3.3320732 | G31: 14.437983 | H31: 14.437983 | I31: 26.529971 | J31: 35.725666
A32: Cloetesville | B32: 2 | C32: 0 | D32: 14 | E32: 0 | F32: 5.1901744 | G32: 14.44 | H32: 21.651799 | I32: 43.633739 | J32: 52.163921
A33: Kayamandi | B33: 2 | C33: 0 | D33: 14 | E33: 0 | F33: 5.0901726 | G33: 14.44 | H33: 21.651799 | I33: 37.633631 | J33: 42.660688
A35: Total | F35: =SUM(F24:F33) -> 36.583822 | H35: =SUM(H24:H33) -> 155.58982 | I35: =SUM(I24:I33) -> 288.93839 | J35: =SUM(J24:J33) -> 351.65757
A37: Avg | F37: =AVERAGE(F24:F33) -> 3.6583822 | I37: =AVERAGE(I24:I33) -> 28.893839 | J37: =AVERAGE(J24:J33) -> 35.165757
A38: Std Dev | F38: =_xlfn.STDEV.S(F24:F33) -> 0.78296164 | I38: =_xlfn.STDEV.S(I24:I33) -> 8.5419861 | J38: =_xlfn.STDEV.S(J24:J33) -> 9.1453624
A40: change in distance | C40: =(I35-I14)/I14 -> -0.069129295
A42: Change in Co2 | C42: =(J35-J14)/J14 -> -0.27733821
B44: NNH | C44: CVRP | D44: Variation
A45: Unipark | B45: 24.427175 | C45: 21.195711 | D45: =C45-B45 -> -3.231464
A46: Simonwyk | B46: 18.655762 | C46: 17.722821 | D46: =C46-B46 -> -0.932941
A47: Paradyskloof | B47: 25.22283 | C47: 25.18476 | D47: =C47-B47 -> -0.03807
A48: Welgevonden | B48: 31.814599 | C48: 28.235207 | D48: =C48-B48 -> -3.579392
A49: Die Boord | B49: 23.538345 | C49: 22.595639 | D49: =C49-B49 -> -0.942706
A50: Idas Valley | B50: 30.756293 | C50: 26.529971 | D50: =C50-B50 -> -4.226322
A51: Cloetesville | B51: 52.981711 | C51: 43.633739 | D51: =C51-B51 -> -9.347972
...

Sheet Case study app data 2
C1: SMART SYSTEM WITH NEAREST DESTINATION RULE | M1: =CORREL(I3:I20,J3:J20) -> 0.97294978
A2: Cluster | B2: Truck ID | C2: Cum collection requests received | D2: Completed collection requests | E2: Avg collection requests queue length | F2: Total travel time (hrs) | G2: Avg filling level at disposal (m3) | H2: Total Waste Disposed | I2: Total Distance Travelled | J2: CO2 emission | L2: km / m3 | M2: CO2 / km | N2: CO2 / m3
A3: Uniepark 1 | B3: 1 | C3: 14 | D3: 14 | E3: 7.5 | F3: 3.4069066 | G3: 14.437983 | H3: 14.437983 | I3: 24.427175 | J3: 38.77553 | M3: =J3/I3 -> 1.5873931
A4: Simonwyk 1 | B4: 1 | C4: 14 | D4: 14 | E4: 7.5 | F4: 3.3107164 | G4: 14.437983 | H4: 14.437983 | I4: 18.655762 | J4: 28.37817 | M4: =J4/I4 -> 1.5211477
A5: Brandwacht 1 | B5: 1 | C5: 14 | D5: 14 | E5: 7.5 | F5: 3.7272152 | G5: 14.437983 | H5: 14.437983 | I5: 43.64569 | J5: 73.993574 | M5: =J5/I5 -> 1.6953237
A6: Paradyskloof 1 | B6: 1 | C6: 14 | D6: 14 | E6: 7.5 | F6: 3.4201675 | G6: 14.437983 | H6: 14.437983 | I6: 25.22283 | J6: 39.731293 | M6: =J6/I6 -> 1.5752116
A7: Welgevonden 1 | B7: 1 | C7: 14 | D7: 14 | E7: 7.5 | F7: 3.5300303 | G7: 14.437983 | H7: 14.437983 | I7: 31.814599 | J7: 51.53186 | M7: =J7/I7 -> 1.6197551
A8: Die Boord 1 | B8: 1 | C8: 14 | D8: 14 | E8: 7.5 | F8: 3.3920927 | G8: 14.437983 | H8: 14.437983 | I8: 23.538345 | J8: 36.972799 | M8: =J8/I8 -> 1.5707476
A9: Idas Valley 1 | B9: 1 | C9: 14 | D9: 14 | E9: 7.5 | F9: 3.5123919 | G9: 14.437983 | H9: 14.437983 | I9: 30.756293 | J9: 50.675747 | M9: =J9/I9 -> 1.6476546
A10: Cloetesville 1 | B10: 2 | C10: 14 | D10: 14 | E10: 7.5 | F10: 5.5722356 | G10: 14.44 | H10: 21.651799 | I10: 52.981711 | J10: 83.041414 | M10: =J10/I10 -> 1.56736
A11: Khayamandi 1 | B11: 2 | C11: 14 | D11: 14 | E11: 7.5 | F11: 5.3690975 | G11: 14.44 | H11: 21.651799 | I11: 40.793427 | J11: 57.793922 | M11: =J11/I11 -> 1.4167459
A12: Uniepark 2 | B12: 1 | C12: 10 | D12: 10 | E12: 5.5 | F12: 2.9338229 | G12: 10.13809 | H12: 10.13809 | I12: 21.764179 | J12: 28.812864 | M12: =J12/I12 -> 1.3238663
A13: Simonwyk 2 2 | B13: 1 | C13: 10 | D13: 10 | E13: 5.5 | F13: 2.8807076 | G13: 10.13809 | H13: 10.13809 | I13: 18.577262 | J13: 23.954286 | M13: =J13/I13 -> 1.2894411
A14: Brandwacht 2 | B14: 1 | C14: 10 | D14: 10 | E14: 5.5 | F14: 3.1566754 | G14: 10.13809 | H14: 10.13809 | I14: 35.13533 | J14: 48.936418 | M14: =J14/I14 -> 1.392798
... A20: Khayamandi 2 | B20: 1 | C20: 10 | D20: 10 | E20: 5.5 | F20: 2.9455301 | G20: 15.203879 | H20: 15.203879 | I20: 22.466607 | J20: 35.509214 | M20: =J20/I20 -> 1.580533
A22: Total | F22: =SUM(F3:F20) -> 62.187237 | H22: =SUM(H3:H20) -> 245.74387 | I22: =SUM(I3:I20) -> 520.23205 | J22: =SUM(J3:J20) -> 782.46036
A24: Avg | F24: =AVERAGE(F3:F20) -> 3.4548465 | H24: =AVERAGE(H3:H20) -> 13.652437 | I24: =AVERAGE(I3:I20) -> 28.90178 | J24: =AVERAGE(J3:J20) -> 43.47002 | M24: =AVERAGE(M3:M20) -> 1.4874991
A25: Std Dev | F25: =_xlfn.STDEV.S(F3:F20) -> 0.77615504 | H25: =_xlfn.STDEV.S(H3:H20) -> 3.6264352 | I25: =_xlfn.STDEV.S(I3:I20) -> 9.3467097 | J25: =_xlfn.STDEV.S(J3:J20) -> 16.131635 | M25: =_xlfn.STDEV.S(M3:M20) -> 0.1423788
C29: SMART SYSTEM WITH OPTIMAL SOLUTION
A31: Cluster | B31: Truck ID | C31: Cum collection requests received | D31: Completed collection requests | E31: Avg collection requests queue length | F31: Total travel time (hrs) | G31: Avg filling level at disposal (m3) | H31: Total Waste Disposed | I31: Total Distance Travelled | J31: CO2 emission | M31: CO2 / km
A32: Unipark | B32: 1 | C32: 0 | D32: 14 | E32: 0 | F32: 3.2431689 | G32: 14.437983 | H32: 14.437983 | I32: 21.195711 | J32: 27.435017 | M32: =J32/I32 -> 1.2943664
A33: Simonwyk | B33: 1 | C33: 0 | D33: 14 | E33: 0 | F33: 3.1852874 | G33: 14.437983 | H33: 14.437983 | I33: 17.722821 | J33: 22.745979 | M33: =J33/I33 -> 1.2834288
A34: Brandwacht | B34: 1 | C34: 0 | D34: 14 | E34: 0 | F34: 3.3335544 | G34: 14.437983 | H34: 14.437983 | I34: 26.618844 | J34: 32.812999 | M34: =J34/I34 -> 1.2326981
A35: Paradyskloof | B35: 1 | C35: 0 | D35: 14 | E35: 0 | F35: 3.309653 | G35: 14.437983 | H35: 14.437983 | I35: 25.18476 | J35: 31.860826 | M35: =J35/I35 -> 1.2650836
A36: Welgevonden | B36: 1 | C36: 0 | D36: 14 | E36: 0 | F36: 3.3604938 | G36: 14.437983 | H36: 14.437983 | I36: 28.235207 | J36: 34.678868 | M36: =J36/I36 -> 1.2282137
A37: Die Boord | B37: 1 | C37: 0 | D37: 14 | E37: 0 | F37: 3.266501 | G37: 14.437983 | H37: 14.437983 | I37: 22.595639 | J37: 26.410447 | M37: =J37/I37 -> 1.1688294
A38: Idas Valley | B38: 1 | C38: 0 | D38: 14 | E38: 0 | F38: 3.3320732 | G38: 14.437983 | H38: 14.437983 | I38: 26.529971 | J38: 35.725666 | M38: =J38/I38 -> 1.3466153
A39: Cloetesville | B39: 2 | C39: 0 | D39: 14 | E39: 0 | F39: 5.1901744 | G39: 14.44 | H39: 21.651799 | I39: 43.633739 | J39: 52.163921 | M39: =J39/I39 -> 1.1954951
A40: Kayamandi | B40: 2 | C40: 0 | D40: 14 | E40: 0 | F40: 5.0901726 | G40: 14.44 | H40: 21.651799 | I40: 37.633631 | J40: 42.660688 | M40: =J40/I40 -> 1.1335789
A41: Uniepark 2 | B41: 1 | C41: 0 | D41: 10 | E41: 0 | F41: 2.8419038 | G41: 10.180678 | H41: 10.180678 | I41: 20.779125 | J41: 23.487738 | M41: =J41/I41 -> 1.1303526
A42: Simonwyk 2 | B42: 1 | C42: 0 | D42: 10 | E42: 0 | F42: 2.7897692 | G42: 10.180678 | H42: 10.180678 | I42: 17.651052 | J42: 20.484634 | M42: =J42/I42 -> 1.1605333
A43: Brandwacht 2 | B43: 1 | C43: 0 | D43: 10 | E43: 0 | F43: 2.9398029 | G43: 10.13809 | H43: 10.13809 | I43: 26.653075 | J43: 29.975883 | M43: =J43/I43 -> 1.1246688
... A49: Khayamandi 2 | B49: 1 | C49: 0 | D49: 10 | E49: 0 | F49: 2.8887435 | G49: 15.203879 | H49: 15.203879 | I49: 23.589507 | J49: 29.633037 | M49: =J49/I49 -> 1.2561957
A51: Total | F51: =SUM(F32:F48) -> 56.96881 | H51: =SUM(H32:H48) -> 230.62517 | I51: =SUM(I32:I49) -> 494.52289 | J51: =SUM(J32:J48) -> 563.99905
A53: Avg | F53: =AVERAGE(F32:F40) -> 3.701231 | I53: =AVERAGE(I32:I40) -> 27.705591 | J53: =AVERAGE(J32:J40) -> 34.054935 | M53: =AVERAGE(M32:M49) -> 1.2015519
A54: Std Dev | F54: =_xlfn.STDEV.S(F32:F40) -> 0.81792562 | I54: =_xlfn.STDEV.S(I32:I40) -> 8.1364604 | J54: =_xlfn.STDEV.S(J32:J40) -> 8.9560422 | M54: =_xlfn.STDEV.S(M32:M49) -> 0.0813865
A56: change in distance | C56: =(I51-I22)/I22 -> -0.049418624
A58: Change in Co2 | C58: =(J51-J22)/J22 -> -0.27919792
B60: Travel Distance | E60: CO2 emissions
B61: NNH | C61: C-VRP | D61: change | E61: NNH | F61: C-VRP | G61: change
...

Sheet col requests
A1: First sampling | E1: Second | F1: sampling | H1: ID in OM input
A2: PUP_ID | B2: Cluster | C2: Waste_qty | E2: PUP_ID | F2: Cluster | G2: Waste_qty
A3: 13 | B3: Uniepark | C3: 1.0518704 | E3: 13 | F3: Uniepark | G3: 0.92558391 | H3: 11 | I3: 13
A4: 12 | B4: Uniepark | C4: 1.0460699 | E4: 12 | F4: Uniepark | G4: 1.1450214 | H4: 10 | I4: 12
A5: 11 | B5: Uniepark | C5: 0.99401018 | E5: 11 | F5: Uniepark | G5: 0.98110423 | H5: 9 | I5: 11
A6: 10 | B6: Uniepark | C6: 0.98997341 | E6: 10 | F6: Uniepark | G6: 1.0945572 | H6: 8 | I6: 10
A7: 9 | B7: Uniepark | C7: 1.0397718 | E7: 9 | F7: Uniepark | G7: 0.93091986 | H7: 7 | I7: 9
A8: 8 | B8: Uniepark | C8: 0.94921825 | E8: 8 | F8: Uniepark | G8: 0.98794148 | H8: 6 | I8: 8
A9: 7 | B9: Uniepark | C9: 1.0366646 | E9: 7 | F9: Uniepark | G9: 0.92082539 | H9: 5 | I9: 7
A10: 6 | B10: Uniepark | C10: 0.99751684 | E10: 6 | F10: Uniepark | G10: 1.0940935 | H10: 4 | I10: 6
A11: 5 | B11: Uniepark | C11: 1.0930693 | E11: 5 | F11: Uniepark | G11: 1.0108894 | H11: 3 | I11: 5
A12: 4 | B12: Uniepark | C12: 0.98251315 | E12: 4 | F12: Uniepark | G12: 1.0471538 | H12: 2 | I12: 4
A13: 3 | B13: Uniepark | C13: 0.97665572 | E13: 13 | F13: Simonswyk | G13: 0.92558391 | H13: 11 | I13: 13
A14: 2 | B14: Uniepark | C14: 1.1148798 | E14: 12 | F14: Simonswyk | G14: 1.1450214 | H14: 10 | I14: 12
... A92: 8 | B92: Die Boord | C92: 0.94921825 | E92: 205 | F92: Kayamandi2 | G92: 1.5703314 | H92: 2 | I92: 205
A93: 7 | B93: Die Boord | C93: 1.0366646
A94: 6 | B94: Die Boord | C94: 0.99751684
A95: 5 | B95: Die Boord | C95: 1.0930693
A96: 4 | B96: Die Boord | C96: 0.98251315
A97: 3 | B97: Die Boord | C97: 0.97665572
A98: 2 | B98: Die Boord | C98: 1.1148798
A99: 1 | B99: Die Boord | C99: 1.0368314
A100: 0 | B100: Die Boord | C100: 1.1289384
A101: 13 | B101: Cloetesville | C101: 1.5773715
A102: 12 | B102: Cloetesville | C102: 1.5686939
A103: 11 | B103: Cloetesville | C103: 1.4907063
A104: 10 | B104: Cloetesville | C104: 1.4846804
... A142: 13 | B142: Idas Valey | C142: 1.0518704

Sheet Sheet4
A1: 0 | B1: 1.1289384
A2: 1 | B2: 1.0368314
A3: 2 | B3: 1.1148798
A4: 3 | B4: 0.97665572
A5: 4 | B5: 0.98251315
A6: 5 | B6: 1.0930693
A7: 6 | B7: 0.99751684
A8: 7 | B8: 1.0366646
A9: 8 | B9: 0.94921825
A10: 9 | B10: 1.0397718
A11: 10 | B11: 0.98997341
A12: 11 | B12: 0.99401018
... A14: 13 | B14: 1.0518704

Sheet optimalRoutes rawdata (2)
A1: Cluster | B1: Truck | C1: Depot | D1: Pup1 | E1: Pup2 | F1: Pup3 | G1: Pup4 | H1: Pup5 | I1: Pup6 | J1: Pup7 | K1: Pup8 | L1: Pup9 | M1: Pup10 | N1: LF | P1: computation time
A2: Uniepark | B2: 3 | C2: 0 | D2: 2 | E2: 9 | F2: 6 | G2: 5 | H2: 7 | I2: 10 | J2: 8 | K2: 4 | L2: 11 | M2: 3 | N2: 1
A3: Simonswyk | B3: 3 | C3: 0 | D3: 11 | E3: 3 | F3: 10 | G3: 5 | H3: 4 | I3: 6 | J3: 8 | K3: 7 | L3: 9 | M3: 2 | N3: 1
A4: Brandwacht | B4: 2 | C4: 0 | D4: 3 | E4: 9 | F4: 6 | G4: 2 | H4: 8 | I4: 7 | J4: 4 | K4: 5 | L4: 10 | M4: 11 | N4: 1 | P4: 0.4539
A5: Paradyskloof | B5: 1 | C5: 0 | D5: 11 | E5: 5 | F5: 6 | G5: 10 | H5: 2 | I5: 7 | J5: 9 | K5: 8 | L5: 3 | M5: 4 | N5: 1 | P5: 0.3528
A6: Welgevonden | B6: 3 | C6: 0 | D6: 10 | E6: 7 | F6: 9 | G6: 6 | H6: 3 | I6: 2 | J6: 4 | K6: 11 | L6: 5 | M6: 8 | N6: 1 | P6: 1.1055 | Q6: 3,"[0, 10, 7, 9, 6, 3, 2, 4, 11, 5, 8, 1]"
A7: Die Boord | B7: 2 | C7: 0 | D7: 5 | E7: 7 | F7: 4 | G7: 9 | H7: 2 | I7: 10 | J7: 3 | K7: 6 | L7: 8 | M7: 11 | N7: 1 | P7: 1.298 | Q7: 2,"[0, 5, 7, 4, 9, 2, 10, 3, 6, 8, 11, 1]"
A8: Idas Valley | B8: 0 | C8: 0 | D8: 2 | E8: 8 | F8: 6 | G8: 4 | H8: 5 | I8: 10 | J8: 9 | K8: 11 | L8: 3 | M8: 7 | N8: 1 | P8: 0.4821 | Q8: 0,"[0, 2, 8, 6, 4, 5, 10, 9, 11, 3, 7, 1]"
A9: Cloetesville | B9: 0 | C9: 0 | D9: 3 | E9: 10 | F9: 2 | G9: 6 | H9: 8 | I9: 7 | J9: 5 | K9: 9 | L9: 11 | M9: 4 | N9: 1 | P9: 0.2378 | Q9: 0,"[0, 3, 10, 2, 6, 8, 7, 5, 9, 11, 4, 1]"
A10: Kayamandi | B10: 1 | C10: 0 | D10: 2 | E10: 10 | F10: 4 | G10: 11 | H10: 8 | I10: 5 | J10: 9 | K10: 6 | L10: 7 | M10: 3 | N10: 1 | P10: 1.6157 | Q10: 0,"[0, 2, 10, 4, 11, 8, 5, 9, 6, 7, 3, 1]"
A13: AssignedTruck_ID | B13: pupID | C13: cluster_name | D13: latitude | E13: longitude | F13: wasteQty | H13: AssignedTruck_ID | I13: pupID | J13: cluster_name | K13: latitude | L13: longitude | M13: wasteQty | P13: pupID | Q13: cluster_name | R13: latitude | S13: longitude | T13: wasteQty | V13: AssignedTruck_ID | W13: pupID | X13: cluster_name | Y13: latitude | Z13: longitude | AA13: wasteQty
A14: 0 | B14: 4 | C14: Uniepark | D14: =VLOOKUP(B14,[1]Uniepark!$A:$D,3,FALSE) -> -33.927951 | E14: =VLOOKUP(B14,[1]Uniepark!$A:$D,4,FALSE) -> 18.882126 | F14: =VLOOKUP(B14,'col requests'!A$18:C$31,3,FALSE) -> 0.98251315 | H14: 0 | I14: 13 | J14: Simonswyk | K14: =VLOOKUP($I14,[1]Simonswyk!$A:$D,3,FALSE) -> -33.929706 | L14: =VLOOKUP($I14,[1]Simonswyk!$A:$D,4,FALSE) -> 18.879036 | M14: =VLOOKUP(I14,'col requests'!A$17:C$30,3,FALSE) -> 1.0518704 | N14: =I14+2 -> 15 | O14: 0 | P14: 9 | Q14: Brandwacht | R14: =VLOOKUP($P14,[1]Brandwacht!$A:$D,3,FALSE) -> -33.953875 | S14: =VLOOKUP($P14,[1]Brandwacht!$A:$D,4,FALSE) -> 18.87407 | T14: =VLOOKUP(P14,'col requests'!E$23:G$32,3,FALSE) -> 1.0108894 | U14: =VLOOKUP(P14,'col requests'!H$23:I$32,2,FALSE) -> 15 | V14: 0 | W14: 58 | X14: Paradyskloof | Y14: =VLOOKUP($W14,[1]Paradyskloof!$A:$D,3,FALSE) -> -33.96148 | Z14: =VLOOKUP($W14,[1]Paradyskloof!$A:$D,4,FALSE) -> 18.850487 | AA14: =VLOOKUP(W14,'col requests'!E$33:G$42,3,FALSE) -> 0.92558391 | AB14: =VLOOKUP(W14,'col requests'!H$33:I$42,2,FALSE) -> #N/A
A15: 0 | B15: 11 | C15: Uniepark | D15: =VLOOKUP(B15,[1]Uniepark!$A:$D,3,FALSE) -> -33.929215 | E15: =VLOOKUP(B15,[1]Uniepark!$A:$D,4,FALSE) -> 18.883699 | F15: =VLOOKUP(B15,'col requests'!A$18:C$31,3,FALSE) -> 0.99401018 | H15: 0 | I15: 5 | J15: Simonswyk | K15: =VLOOKUP($I15,[1]Simonswyk!$A:$D,3,FALSE) -> -33.929935 | L15: =VLOOKUP($I15,[1]Simonswyk!$A:$D,4,FALSE) -> 18.87915 | M15: =VLOOKUP(I15,'col requests'!A$17:C$30,3,FALSE) -> 1.0930693 | N15: =I15+2 -> 7 | O15: 0 | P15: 15 | Q15: Brandwacht | R15: =VLOOKUP($P15,[1]Brandwacht!$A:$D,3,FALSE) -> -33.955455 | S15: =VLOOKUP($P15,[1]Brandwacht!$A:$D,4,FALSE) -> 18.874536 | T15: =VLOOKUP(P15,'col requests'!E$23:G$32,3,FALSE) -> 0.98110423 | U15: =VLOOKUP(P15,'col requests'!H$23:I$32,2,FALSE) -> #N/A | V15: 0 | W15: 52 | X15: Paradyskloof | Y15: =VLOOKUP($W15,[1]Paradyskloof!$A:$D,3,FALSE) -> -33.962206 | Z15: =VLOOKUP($W15,[1]Paradyskloof!$A:$D,4,FALSE) -> 18.849764 | AA15: =VLOOKUP(W15,'col requests'!E$33:G$42,3,FALSE) -> 0.92082539 | AB15: =VLOOKUP(W15,'col requests'!H$33:I$42,2,FALSE) -> #N/A
A16: 0 | B16: 8 | C16: Uniepark | D16: =VLOOKUP(B16,[1]Uniepark!$A:$D,3,FALSE) -> -33.930483 | E16: =VLOOKUP(B16,[1]Uniepark!$A:$D,4,FALSE) -> 18.886414 | F16: =VLOOKUP(B16,'col requests'!A$18:C$31,3,FALSE) -> 0.94921825 | H16: 0 | I16: 12 | J16: Simonswyk | K16: =VLOOKUP($I16,[1]Simonswyk!$A:$D,3,FALSE) -> -33.929378 | L16: =VLOOKUP($I16,[1]Simonswyk!$A:$D,4,FALSE) -> 18.881672 | M16: =VLOOKUP(I16,'col requests'!A$17:C$30,3,FALSE) -> 1.0460699 | N16: =I16+2 -> 14 | O16: 0 | P16: 12 | Q16: Brandwacht | R16: =VLOOKUP($P16,[1]Brandwacht!$A:$D,3,FALSE) -> -33.957617 | S16: =VLOOKUP($P16,[1]Brandwacht!$A:$D,4,FALSE) -> 18.874461 | T16: =VLOOKUP(P16,'col requests'!E$23:G$32,3,FALSE) -> 0.98794148 | U16: =VLOOKUP(P16,'col requests'!H$23:I$32,2,FALSE) -> #N/A | V16: 0 | W16: 53 | X16: Paradyskloof | Y16: =VLOOKUP($W16,[1]Paradyskloof!$A:$D,3,FALSE) -> -33.961298 | Z16: =VLOOKUP($W16,[1]Paradyskloof!$A:$D,4,FALSE) -> 18.851054 | AA16: =VLOOKUP(W16,'col requests'!E$33:G$42,3,FALSE) -> 0.98794148 | AB16: =VLOOKUP(W16,'col requests'!H$33:I$42,2,FALSE) -> #N/A
A17: 0 | B17: 7 | C17: Uniepark | D17: =VLOOKUP(B17,[1]Uniepark!$A:$D,3,FALSE) -> -33.930506 | E17: =VLOOKUP(B17,[1]Uniepark!$A:$D,4,FALSE) -> 18.891216 | F17: =VLOOKUP(B17,'col requests'!A$18:C$31,3,FALSE) -> 1.0366646 | H17: 0 | I17: 7 | J17: Simonswyk | K17: =VLOOKUP($I17,[1]Simonswyk!$A:$D,3,FALSE) -> -33.9279 | L17: =VLOOKUP($I17,[1]Simonswyk!$A:$D,4,FALSE) -> 18.881793 | M17: =VLOOKUP(I17,'col requests'!A$17:C$30,3,FALSE) -> 1.0366646 | N17: =I17+2 -> 9 | O17: 0 | P17: 8 | Q17: Brandwacht | R17: =VLOOKUP($P17,[1]Brandwacht!$A:$D,3,FALSE) -> -33.955469 | S17: =VLOOKUP($P17,[1]Brandwacht!$A:$D,4,FALSE) -> 18.865177 | T17: =VLOOKUP(P17,'col requests'!E$23:G$32,3,FALSE) -> 1.0471538 | U17: =VLOOKUP(P17,'col requests'!H$23:I$32,2,FALSE) -> 14 | V17: 0 | W17: 57 | X17: Paradyskloof | Y17: =VLOOKUP($W17,[1]Paradyskloof!$A:$D,3,FALSE) -> -33.96001 | Z17: =VLOOKUP($W17,[1]Paradyskloof!$A:$D,4,FALSE) -> 18.853047 | AA17: =VLOOKUP(W17,'col requests'!E$33:G$42,3,FALSE) -> 1.1450214 | AB17: =VLOOKUP(W17,'col requests'!H$33:I$42,2,FALSE) -> #N/A
A18: 0 | B18: 9 | C18: Uniepark | D18: =VLOOKUP(B18,[1]Uniepark!$A:$D,3,FALSE) -> -33.929094 | E18: =VLOOKUP(B18,[1]Uniepark!$A:$D,4,FALSE) -> 18.89087 | F18: =VLOOKUP(B18,'col requests'!A$18:C$31,3,FALSE) -> 1.0397718 | H18: 0 | I18: 6 | J18: Simonswyk | K18: =VLOOKUP($I18,[1]Simonswyk!$A:$D,3,FALSE) -> -33.928585 | L18: =VLOOKUP($I18,[1]Simonswyk!$A:$D,4,FALSE) -> 18.877707 | M18: =VLOOKUP(I18,'col requests'!A$17:C$30,3,FALSE) -> 0.99751684 | N18: =I18+2 -> 8 | O18: 0 | P18: 14 | Q18: Brandwacht | R18: =VLOOKUP($P18,[1]Brandwacht!$A:$D,3,FALSE) -> -33.957746 | S18: =VLOOKUP($P18,[1]Brandwacht!$A:$D,4,FALSE) -> 18.872521 | T18: =VLOOKUP(P18,'col requests'!E$23:G$32,3,FALSE) -> 1.0945572 | U18: =VLOOKUP(P18,'col requests'!H$23:I$32,2,FALSE) -> #N/A | V18: 0 | W18: 49 | X18: Paradyskloof | Y18: =VLOOKUP($W18,[1]Paradyskloof!$A:$D,3,FALSE) -> -33.961347 | Z18: =VLOOKUP($W18,[1]Paradyskloof!$A:$D,4,FALSE) -> 18.854739 | AA18: =VLOOKUP(W18,'col requests'!E$33:G$42,3,FALSE) -> 1.0471538 | AB18: =VLOOKUP(W18,'col requests'!H$33:I$42,2,FALSE) -> #N/A
A19: 0 | B19: 12 | C19: Uniepark | D19: =VLOOKUP(B19,[1]Uniepark!$A:$D,3,FALSE) -> -33.932355 | E19: =VLOOKUP(B19,[1]Uniepark!$A:$D,4,FALSE) -> 18.891066 | F19: =VLOOKUP(B19,'col requests'!A$18:C$31,3,FALSE) -> 1.0460699 | H19: 0 | I19: 8 | J19: Simonswyk | K19: =VLOOKUP($I19,[1]Simonswyk!$A:$D,3,FALSE) -> -33.927881 | L19: =VLOOKUP($I19,[1]Simonswyk!$A:$D,4,FALSE) -> 18.877922 | M19: =VLOOKUP(I19,'col requests'!A$17:C$30,3,FALSE) -> 0.94921825 | N19: =I19+2 -> 10 | O19: 0 | P19: 13 | Q19: Brandwacht | R19: =VLOOKUP($P19,[1]Brandwacht!$A:$D,3,FALSE) -> -33.958087 | S19: =VLOOKUP($P19,[1]Brandwacht!$A:$D,4,FALSE) -> 18.867935 | T19: =VLOOKUP(P19,'col requests'!E$23:G$32,3,FALSE) -> 0.93091986 | U19: =VLOOKUP(P19,'col requests'!H$23:I$32,2,FALSE) -> #N/A | V19: 0 | W19: 54 | X19: Paradyskloof | Y19: =VLOOKUP($W19,[1]Paradyskloof!$A:$D,3,FALSE) -> -33.963533 | Z19: =VLOOKUP($W19,[1]Paradyskloof!$A:$D,4,FALSE) -> 18.854814 | AA19: =VLOOKUP(W19,'col requests'!E$33:G$42,3,FALSE) -> 0.93091986 | AB19: =VLOOKUP(W19,'col requests'!H$33:I$42,2,FALSE) -> #N/A
A20: 0 | B20: 10 | C20: Uniepark | D20: =VLOOKUP(B20,[1]Uniepark!$A:$D,3,FALSE) -> -33.930209 | E20: =VLOOKUP(B20,[1]Uniepark!$A:$D,4,FALSE) -> 18.887019 | F20: =VLOOKUP(B20,'col requests'!A$18:C$31,3,FALSE) -> 0.98997341 | H20: 0 | I20: 10 | J20: Simonswyk | K20: =VLOOKUP($I20,[1]Simonswyk!$A:$D,3,FALSE) -> -33.927662 | L20: =VLOOKUP($I20,[1]Simonswyk!$A:$D,4,FALSE) -> 18.87841 | M20: =VLOOKUP(I20,'col requests'!A$17:C$30,3,FALSE) -> 0.98997341 | N20: =I20+2 -> 12 | O20: 0 | P20: 10 | Q20: Brandwacht | R20: =VLOOKUP($P20,[1]Brandwacht!$A:$D,3,FALSE) -> -33.955155 | S20: =VLOOKUP($P20,[1]Brandwacht!$A:$D,4,FALSE) -> 18.866386 | T20: =VLOOKUP(P20,'col requests'!E$23:G$32,3,FALSE) -> 1.0940935 | U20: =VLOOKUP(P20,'col requests'!H$23:I$32,2,FALSE) -> 16 | V20: 0 | W20: 56 | X20: Paradyskloof | Y20: =VLOOKUP($W20,[1]Paradyskloof!$A:$D,3,FALSE) -> -33.967438 | Z20: =VLOOKUP($W20,[1]Paradyskloof!$A:$D,4,FALSE) -> 18.849995 | AA20: =VLOOKUP(W20,'col requests'!E$33:G$42,3,FALSE) -> 0.98110423 | AB20: =VLOOKUP(W20,'col requests'!H$33:I$42,2,FALSE) -> #N/A
A21: 0 | B21: 6 | C21: Uniepark | D21: =VLOOKUP(B21,[1]Uniepark!$A:$D,3,FALSE) -> -33.931364 | E21: =VLOOKUP(B21,[1]Uniepark!$A:$D,4,FALSE) -> 18.886148 | F21: =VLOOKUP(B21,'col requests'!A$18:C$31,3,FALSE) -> 0.99751684 | H21: 0 | I21: 9 | J21: Simonswyk | K21: =VLOOKUP($I21,[1]Simonswyk!$A:$D,3,FALSE) -> -33.92677 | L21: =VLOOKUP($I21,[1]Simonswyk!$A:$D,4,FALSE) -> 18.881514 | M21: =VLOOKUP(I21,'col requests'!A$17:C$30,3,FALSE) -> 1.0397718 | N21: =I21+2 -> 11 | O21: 0 | P21: 11 | Q21: Brandwacht | R21: =VLOOKUP($P21,[1]Brandwacht!$A:$D,3,FALSE) -> -33.954015 | S21: =VLOOKUP($P21,[1]Brandwacht!$A:$D,4,FALSE) -> 18.859761 | T21: =VLOOKUP(P21,'col requests'!E$23:G$32,3,FALSE) -> 0.92082539 | U21: =VLOOKUP(P21,'col requests'!H$23:I$32,2,FALSE) -> 17 | V21: 0 | W21: 55 | X21: Paradyskloof | Y21: =VLOOKUP($W21,[1]Paradyskloof!$A:$D,3,FALSE) -> -33.967353 | Z21: =VLOOKUP($W21,[1]Paradyskloof!$A:$D,4,FALSE) -> 18.859292 | AA21: =VLOOKUP(W21,'col requests'!E$33:G$42,3,FALSE) -> 1.0945572 | AB21: =VLOOKUP(W21,'col requests'!H$33:I$42,2,FALSE) -> #N/A
A22: 0 | B22: 13 | C22: Uniepark | D22: =VLOOKUP(B22,[1]Uniepark!$A:$D,3,FALSE) -> -33.932765 | E22: =VLOOKUP(B22,[1]Uniepark!$A:$D,4,FALSE) -> 18.887796 | F22: =VLOOKUP(B22,'col requests'!A$18:C$31,3,FALSE) -> 1.0518704 | H22: 0 | I22: 11 | J22: Simonswyk | K22: =VLOOKUP($I22,[1]Simonswyk!$A:$D,3,FALSE) -> -33.926867 | L22: =VLOOKUP($I22,[1]Simonswyk!$A:$D,4,FALSE) -> 18.875734 | M22: =VLOOKUP(I22,'col requests'!A$17:C$30,3,FALSE) -> 0.99401018 | N22: =I22+2 -> 13 | O22: 0 | P22: 16 | Q22: Brandwacht | R22: =VLOOKUP($P22,[1]Brandwacht!$A:$D,3,FALSE) -> -33.953065 | S22: =VLOOKUP($P22,[1]Brandwacht!$A:$D,4,FALSE) -> 18.858232 | T22: =VLOOKUP(P22,'col requests'!E$23:G$32,3,FALSE) -> 1.1450214 | U22: =VLOOKUP(P22,'col requests'!H$23:I$32,2,FALSE) -> #N/A | V22: 0 | W22: 50 | X22: Paradyskloof | Y22: =VLOOKUP($W22,[1]Paradyskloof!$A:$D,3,FALSE) -> -33.963058 | Z22: =VLOOKUP($W22,[1]Paradyskloof!$A:$D,4,FALSE) -> 18.856448 | AA22: =VLOOKUP(W22,'col requests'!E$33:G$42,3,FALSE) -> 1.0108894 | AB22: =VLOOKUP(W22,'col requests'!H$33:I$42,2,FALSE) -> #N/A
A23: 0 | B23: 5 | C23: Uniepark | D23: =VLOOKUP(B23,[1]Uniepark!$A:$D,3,FALSE) -> -33.933051 | E23: =VLOOKUP(B23,[1]Uniepark!$A:$D,4,FALSE) -> 18.887937 | F23: =VLOOKUP(B23,'col requests'!A$18:C$31,3,FALSE) -> 1.0930693 | H23: 0 | I23: 4 | J23: Simonswyk | K23: =VLOOKUP($I23,[1]Simonswyk!$A:$D,3,FALSE) -> -33.925856 | L23: =VLOOKUP($I23,[1]Simonswyk!$A:$D,4,FALSE) -> 18.874465 | M23: =VLOOKUP(I23,'col requests'!A$17:C$30,3,FALSE) -> 0.98251315 | N23: =I23+2 -> 6 | O23: 0 | P23: 17 | Q23: Brandwacht | R23: =VLOOKUP($P23,[1]Brandwacht!$A:$D,3,FALSE) -> -33.958569 | S23: =VLOOKUP($P23,[1]Brandwacht!$A:$D,4,FALSE) -> 18.867551 | T23: =VLOOKUP(P23,'col requests'!E$23:G$32,3,FALSE) -> 0.92558391 | U23: =VLOOKUP(P23,'col requests'!H$23:I$32,2,FALSE) -> #N/A | V23: 0 | W23: 51 | X23: Paradyskloof | Y23: =VLOOKUP($W23,[1]Paradyskloof!$A:$D,3,FALSE) -> -33.960204 | Z23: =VLOOKUP($W23,[1]Paradyskloof!$A:$D,4,FALSE) -> 18.856498 | AA23: =VLOOKUP(W23,'col requests'!E$33:G$42,3,FALSE) -> 1.0940935 | AB23: =VLOOKUP(W23,'col requests'!H$33:I$42,2,FALSE) -> #N/A
A26: AssignedTruck_ID | B26: pupID | C26: cluster_name | D26: latitude | E26: longitude | F26: wasteQty | H26: AssignedTruck_ID | I26: pupID | J26: cluster_name | K26: latitude | L26: longitude | M26: wasteQty | O26: AssignedTruck_ID | P26: pupID | Q26: cluster_name | R26: latitude | S26: longitude | T26: wasteQty
A27: 0 | B27: 70 | C27: Welgevonden | D27: =VLOOKUP($B27,[1]Welgevonden!$A:$D,3,FALSE) -> -33.90304 | E27: =VLOOKUP($B27,[1]Welgevonden!$A:$D,4,FALSE) -> 18.852106 | F27: =VLOOKUP(B27,'col requests'!E$43:G$52,3,FALSE) -> 1.1450214 | G27: =VLOOKUP(B27,'col requests'!H$43:I$52,2,FALSE) -> #N/A | H27: 0 | I27: 67 | J27: Die Boord | K27: =VLOOKUP($I27,'[1]Die Boord'!$A:$D,3,FALSE) -> -33.950467 | L27: =VLOOKUP($I27,'[1]Die Boord'!$A:$D,4,FALSE) -> 18.853719 | M27: =VLOOKUP(I27,'col requests'!E$53:G$62,3,FALSE) -> 0.92082539 | N27: =VLOOKUP(I27,'col requests'!H$53:I$62,2,FALSE) -> #N/A | O27: 0 | P27: 97 | Q27: Idas Valley | R27: =VLOOKUP($P27,'[1]Idas Valley'!$A:$D,3,FALSE) -> -33.925601 | S27: =VLOOKUP($P27,'[1]Idas Valley'!$A:$D,4,FALSE) -> 18.883647 | T27: =VLOOKUP(P27,'col requests'!E$63:G$72,3,FALSE) -> 1.0471538 | U27: =VLOOKUP(P27,'col requests'!H$63:I$72,2,FALSE) -> #N/A
A28: 0 | B28: 67 | C28: Welgevonden | D28: =VLOOKUP($B28,[1]Welgevonden!$A:$D,3,FALSE) -> -33.901707 | E28: =VLOOKUP($B28,[1]Welgevonden!$A:$D,4,FALSE) -> 18.857218 | F28: =VLOOKUP(B28,'col requests'!E$43:G$52,3,FALSE) -> 0.93091986 | G28: =VLOOKUP(B28,'col requests'!H$43:I$52,2,FALSE) -> #N/A | H28: 0 | I28: 69 | J28: Die Boord | K28: =VLOOKUP($I28,'[1]Die Boord'!$A:$D,3,FALSE) -> -33.944119 | L28: =VLOOKUP($I28,'[1]Die Boord'!$A:$D,4,FALSE) -> 18.85122 | M28: =VLOOKUP(I28,'col requests'!E$53:G$62,3,FALSE) -> 0.93091986 | N28: =VLOOKUP(I28,'col requests'!H$53:I$62,2,FALSE) -> #N/A | O28: 0 | P28: 103 | Q28: Idas Valley | R28: =VLOOKUP($P28,'[1]Idas Valley'!$A:$D,3,FALSE) -> -33.91914 | S28: =VLOOKUP($P28,'[1]Idas Valley'!$A:$D,4,FALSE) -> 18.883101 | T28: =VLOOKUP(P28,'col requests'!E$63:G$72,3,FALSE) -> 1.0945572 | U28: =VLOOKUP(P28,'col requests'!H$63:I$72,2,FALSE) -> #N/A
A29: 0 | B29: 69 | C29: Welgevonden | D29: =VLOOKUP($B29,[1]Welgevonden!$A:$D,3,FALSE) -> -33.898522 | E29: =VLOOKUP($B29,[1]Welgevonden!$A:$D,4,FALSE) -> 18.854981 | F29: =VLOOKUP(B29,'col requests'!E$43:G$52,3,FALSE) -> 0.98110423 | G29: =VLOOKUP(B29,'col requests'!H$43:I$52,2,FALSE) -> #N/A | H29: 0 | I29: 66 | J29: Die Boord | K29: =VLOOKUP($I29,'[1]Die Boord'!$A:$D,3,FALSE) -> -33.953255 | L29: =VLOOKUP($I29,'[1]Die Boord'!$A:$D,4,FALSE) -> 18.844482 | M29: =VLOOKUP(I29,'col requests'!E$53:G$62,3,FALSE) -> 1.0940935 | N29: =VLOOKUP(I29,'col requests'!H$53:I$62,2,FALSE) -> #N/A | O29: 0 | P29: 101 | Q29: Idas Valley | R29: =VLOOKUP($P29,'[1]Idas Valley'!$A:$D,3,FALSE) -> -33.924603 | S29: =VLOOKUP($P29,'[1]Idas Valley'!$A:$D,4,FALSE) -> 18.884916 | T29: =VLOOKUP(P29,'col requests'!E$63:G$72,3,FALSE) -> 0.98794148 | U29: =VLOOKUP(P29,'col requests'!H$63:I$72,2,FALSE) -> #N/A
A30: 0 | B30: 66 | C30: Welgevonden | D30: =VLOOKUP($B30,[1]Welgevonden!$A:$D,3,FALSE) -> -33.903105 | E30: =VLOOKUP($B30,[1]Welgevonden!$A:$D,4,FALSE) -> 18.848952 | F30: =VLOOKUP(B30,'col requests'!E$43:G$52,3,FALSE) -> 0.98794148 | G30: =VLOOKUP(B30,'col requests'!H$43:I$52,2,FALSE) -> #N/A | H30: 0 | I30: 71 | J30: Die Boord | K30: =VLOOKUP($I30,'[1]Die Boord'!$A:$D,3,FALSE) -> -33.948448 | L30: =VLOOKUP($I30,'[1]Die Boord'!$A:$D,4,FALSE) -> 18.848027 | M30: =VLOOKUP(I30,'col requests'!E$53:G$62,3,FALSE) -> 0.98110423 | N30: =VLOOKUP(I30,'col requests'!H$53:I$62,2,FALSE) -> #N/A | O30: 0 | P30: 99 | Q30: Idas Valley | R30: =VLOOKUP($P30,'[1]Idas Valley'!$A:$D,3,FALSE) -> -33.923351 | S30: =VLOOKUP($P30,'[1]Idas Valley'!$A:$D,4,FALSE) -> 18.882234 | T30: =VLOOKUP(P30,'col requests'!E$63:G$72,3,FALSE) -> 1.0940935 | U30: =VLOOKUP(P30,'col requests'!H$63:I$72,2,FALSE) -> #N/A
A31: 0 | B31: 63 | C31: Welgevonden | D31: =VLOOKUP($B31,[1]Welgevonden!$A:$D,3,FALSE) -> -33.899029 | E31: =VLOOKUP($B31,[1]Welgevonden!$A:$D,4,FALSE) -> 18.856163 | F31: =VLOOKUP(B31,'col requests'!E$43:G$52,3,FALSE) -> 1.0108894 | G31: =VLOOKUP(B31,'col requests'!H$43:I$52,2,FALSE) -> #N/A | H31: 0 | I31: 64 | J31: Die Boord | K31: =VLOOKUP($I31,'[1]Die Boord'!$A:$D,3,FALSE) -> -33.947725 | L31: =VLOOKUP($I31,'[1]Die Boord'!$A:$D,4,FALSE) -> 18.851712 | M31: =VLOOKUP(I31,'col requests'!E$53:G$62,3,FALSE) -> 1.0471538 | N31: =VLOOKUP(I31,'col requests'!H$53:I$62,2,FALSE) -> #N/A | O31: 0 | P31: 100 | Q31: Idas Valley | R31: =VLOOKUP($P31,'[1]Idas Valley'!$A:$D,3,FALSE) -> -33.920018 | S31: =VLOOKUP($P31,'[1]Idas Valley'!$A:$D,4,FALSE) -> 18.871865 | T31: =VLOOKUP(P31,'col requests'!E$63:G$72,3,FALSE) -> 0.92082539 | U31: =VLOOKUP(P31,'col requests'!H$63:I$72,2,FALSE) -> #N/A
A32: 0 | B32: 62 | C32: Welgevonden | D32: =VLOOKUP($B32,[1]Welgevonden!$A:$D,3,FALSE) -> -33.902201 | E32: =VLOOKUP($B32,[1]Welgevonden!$A:$D,4,FALSE) -> 18.856566 | F32: =VLOOKUP(B32,'col requests'!E$43:G$52,3,FALSE) -> 1.0471538 | G32: =VLOOKUP(B32,'col requests'!H$43:I$52,2,FALSE) -> #N/A | H32: 0 | I32: 72 | J32: Die Boord | K32: =VLOOKUP($I32,'[1]Die Boord'!$A:$D,3,FALSE) -> -33.942902 | L32: =VLOOKUP($I32,'[1]Die Boord'!$A:$D,4,FALSE) -> 18.853422 | M32: =VLOOKUP(I32,'col requests'!E$53:G$62,3,FALSE) -> 1.1450214 | N32: =VLOOKUP(I32,'col requests'!H$53:I$62,2,FALSE) -> #N/A | O32: 0 | P32: 105 | Q32: Idas Valley | R32: =VLOOKUP($P32,'[1]Idas Valley'!$A:$D,3,FALSE) -> -33.918456 | S32: =VLOOKUP($P32,'[1]Idas Valley'!$A:$D,4,FALSE) -> 18.885497 | T32: =VLOOKUP(P32,'col requests'!E$63:G$72,3,FALSE) -> 1.1450214 | U32: =VLOOKUP(P32,'col requests'!H$63:I$72,2,FALSE) -> #N/A
A33: 0 | B33: 64 | C33: Welgevonden | D33: =VLOOKUP($B33,[1]Welgevonden!$A:$D,3,FALSE) -> -33.900331 | E33: =VLOOKUP($B33,[1]Welgevonden!$A:$D,4,FALSE) -> 18.855422 | F33: =VLOOKUP(B33,'col requests'!E$43:G$52,3,FALSE) -> 1.0940935 | G33: =VLOOKUP(B33,'col requests'!H$43:I$52,2,FALSE) -> #N/A | H33: 0 | I33: 65 | J33: Die Boord | K33: =VLOOKUP($I33,'[1]Die Boord'!$A:$D,3,FALSE) -> -33.949522 | L33: =VLOOKUP($I33,'[1]Die Boord'!$A:$D,4,FALSE) -> 18.853673 | M33: =VLOOKUP(I33,'col requests'!E$53:G$62,3,FALSE) -> 1.0108894 | N33: =VLOOKUP(I33,'col requests'!H$53:I$62,2,FALSE) -> #N/A | O33: 0 | P33: 104 | Q33: Idas Valley | R33: =VLOOKUP($P33,'[1]Idas Valley'!$A:$D,3,FALSE) -> -33.926144 | S33: =VLOOKUP($P33,'[1]Idas Valley'!$A:$D,4,FALSE) -> 18.893637 | T33: =VLOOKUP(P33,'col requests'!E$63:G$72,3,FALSE) -> 0.98110423 | U33: =VLOOKUP(P33,'col requests'!H$63:I$72,2,FALSE) -> #N/A
A34: 0 | B34: 71 | C34: Welgevonden | D34: =VLOOKUP($B34,[1]Welgevonden!$A:$D,3,FALSE) -> -33.900694 | E34: =VLOOKUP($B34,[1]Welgevonden!$A:$D,4,FALSE) -> 18.852124 | F34: =VLOOKUP(B34,'col requests'!E$43:G$52,3,FALSE) -> 0.92558391 | G34: =VLOOKUP(B34,'col requests'!H$43:I$52,2,FALSE) -> #N/A | H34: 0 | I34: 68 | J34: Die Boord | K34: =VLOOKUP($I34,'[1]Die Boord'!$A:$D,3,FALSE) -> -33.951852 | L34: =VLOOKUP($I34,'[1]Die Boord'!$A:$D,4,FALSE) -> 18.846144 | M34: =VLOOKUP(I34,'col requests'!E$53:G$62,3,FALSE) -> 0.98794148 | N34: =VLOOKUP(I34,'col requests'!H$53:I$62,2,FALSE) -> #N/A | O34: 0 | P34: 106 | Q34: Idas Valley | R34: =VLOOKUP($P34,'[1]Idas Valley'!$A:$D,3,FALSE) -> -33.924592 | S34: =VLOOKUP($P34,'[1]Idas Valley'!$A:$D,4,FALSE) -> 18.882138 | T34: =VLOOKUP(P34,'col requests'!E$63:G$72,3,FALSE) -> 0.92558391 | U34: =VLOOKUP(P34,'col requests'!H$63:I$72,2,FALSE) -> #N/A
A35: 0 | B35: 65 | C35: Welgevonden | D35: =VLOOKUP($B35,[1]Welgevonden!$A:$D,3,FALSE) -> -33.901233 | E35: =VLOOKUP($B35,[1]Welgevonden!$A:$D,4,FALSE) -> 18.857177 | F35: =VLOOKUP(B35,'col requests'!E$43:G$52,3,FALSE) -> 0.92082539 | G35: =VLOOKUP(B35,'col requests'!H$43:I$52,2,FALSE) -> #N/A | H35: 0 | I35: 70 | J35: Die Boord | K35: =VLOOKUP($I35,'[1]Die Boord'!$A:$D,3,FALSE) -> -33.953125 | L35: =VLOOKUP($I35,'[1]Die Boord'!$A:$D,4,FALSE) -> 18.848006 | M35: =VLOOKUP(I35,'col requests'!E$53:G$62,3,FALSE) -> 1.0945572 | N35: =VLOOKUP(I35,'col requests'!H$53:I$62,2,FALSE) -> #N/A | O35: 0 | P35: 98 | Q35: Idas Valley | R35: =VLOOKUP($P35,'[1]Idas Valley'!$A:$D,3,FALSE) -> -33.925485 | S35: =VLOOKUP($P35,'[1]Idas Valley'!$A:$D,4,FALSE) -> 18.884268 | T35: =VLOOKUP(P35,'col requests'!E$63:G$72,3,FALSE) -> 1.0108894 | U35: =VLOOKUP(P35,'col requests'!H$63:I$72,2,FALSE) -> #N/A
A36: 0 | B36: 68 | C36: Welgevonden | D36: =VLOOKUP($B36,[1]Welgevonden!$A:$D,3,FALSE) -> -33.902402 | E36: =VLOOKUP($B36,[1]Welgevonden!$A:$D,4,FALSE) -> 18.85044 | F36: =VLOOKUP(B36,'col requests'!E$43:G$52,3,FALSE) -> 1.0945572 | G36: =VLOOKUP(B36,'col requests'!H$43:I$52,2,FALSE) -> #N/A | H36: 0 | I36: 73 | J36: Die Boord | K36: =VLOOKUP($I36,'[1]Die Boord'!$A:$D,3,FALSE) -> -33.952521 | L36: =VLOOKUP($I36,'[1]Die Boord'!$A:$D,4,FALSE) -> 18.853811 | M36: =VLOOKUP(I36,'col requests'!E$53:G$62,3,FALSE) -> 0.92558391 | N36: =VLOOKUP(I36,'col requests'!H$53:I$62,2,FALSE) -> #N/A | O36: 0 | P36: 102 | Q36: Idas Valley | R36: =VLOOKUP($P36,'[1]Idas Valley'!$A:$D,3,FALSE) -> -33.922057 | S36: =VLOOKUP($P36,'[1]Idas Valley'!$A:$D,4,FALSE) -> 18.892627 | T36: =VLOOKUP(P36,'col requests'!E$63:G$72,3,FALSE) -> 0.93091986 | U36: =VLOOKUP(P36,'col requests'!H$63:I$72,2,FALSE) -> #N/A
A38: AssignedTruck_ID | B38: pupID | C38: cluster_name | D38: latitude | E38: longitude | F38: wasteQty | H38: AssignedTruck_ID | I38: pupID | J38: cluster_name | K38: latitude | L38: longitude | M38: wasteQty
A39: 0 | B39: 158 | C39: Cloetesville | D39: =VLOOKUP($B39,[1]Cloetesville!$A:$D,3,FALSE) -> -33.901872 | E39: =VLOOKUP($B39,[1]Cloetesville!$A:$D,4,FALSE) -> 18.853965 | F39: =VLOOKUP(B39,'col requests'!E$73:G$82,3,FALSE) -> 1.5160222 | H39: 0 | I39: 205 | J39: Kayamandi1 | K39: =VLOOKUP(I39,[1]Kayamandi2!$A:$D,3,FALSE) -> -33.914869 | L39: =VLOOKUP(I39,[1]Kayamandi2!$A:$D,4,FALSE) -> 18.846732 | M39: =VLOOKUP(I39,'col requests'!E$83:G$92,3,FALSE) -> 1.5703314 | N39: =VLOOKUP(I39,'col requests'!H$83:I$92,2,FALSE) -> #N/A
A40: 0 | B40: 165 | C40: Cloetesville | D40: =VLOOKUP($B40,[1]Cloetesville!$A:$D,3,FALSE) -> -33.908089 | E40: =VLOOKUP($B40,[1]Cloetesville!$A:$D,4,FALSE) -> 18.850993 | F40: =VLOOKUP(B40,'col requests'!E$73:G$82,3,FALSE) -> 1.7169095 | H40: 0 | I40: 213 | J40: Kayamandi1 | K40: =VLOOKUP(I40,[1]Kayamandi2!$A:$D,3,FALSE) -> -33.918537 | L40: =VLOOKUP(I40,[1]Kayamandi2!$A:$D,4,FALSE) -> 18.845462 | M40: =VLOOKUP(I40,'col requests'!E$83:G$92,3,FALSE) -> 1.7169095 | N40: =VLOOKUP(I40,'col requests'!H$83:I$92,2,FALSE) -> #N/A
A41: 0 | B41: 157 | C41: Cloetesville | D41: =VLOOKUP($B41,[1]Cloetesville!$A:$D,3,FALSE) -> -33.912657 | E41: =VLOOKUP($B41,[1]Cloetesville!$A:$D,4,FALSE) -> 18.85598 | F41: =VLOOKUP(B41,'col requests'!E$73:G$82,3,FALSE) -> 1.5703314 | H41: 0 | I41: 207 | J41: Kayamandi1 | K41: =VLOOKUP(I41,[1]Kayamandi2!$A:$D,3,FALSE) -> -33.915073 | L41: =VLOOKUP(I41,[1]Kayamandi2!$A:$D,4,FALSE) -> 18.846373 | M41: =VLOOKUP(I41,'col requests'!E$83:G$92,3,FALSE) -> 1.6406372 | N41: =VLOOKUP(I41,'col requests'!H$83:I$92,2,FALSE) -> #N/A
A42: 0 | B42: 161 | C42: Cloetesville | D42: =VLOOKUP($B42,[1]Cloetesville!$A:$D,3,FALSE) -> -33.909625 | E42: =VLOOKUP($B42,[1]Cloetesville!$A:$D,4,FALSE) -> 18.859047 | F42: =VLOOKUP(B42,'col requests'!E$73:G$82,3,FALSE) -> 1.481643 | H42: 0 | I42: 214 | J42: Kayamandi1 | K42: =VLOOKUP(I42,[1]Kayamandi2!$A:$D,3,FALSE) -> -33.918262 | L42: =VLOOKUP(I42,[1]Kayamandi2!$A:$D,4,FALSE) -> 18.847224 | M42: =VLOOKUP(I42,'col requests'!E$83:G$92,3,FALSE) -> 1.3882435 | N42: =VLOOKUP(I42,'col requests'!H$83:I$92,2,FALSE) -> #N/A
A43: 0 | B43: 163 | C43: Cloetesville | D43: =VLOOKUP($B43,[1]Cloetesville!$A:$D,3,FALSE) -> -33.919651 | E43: =VLOOKUP($B43,[1]Cloetesville!$A:$D,4,FALSE) -> 18.853664 | F43: =VLOOKUP(B43,'col requests'!E$73:G$82,3,FALSE) -> 1.6413258 | H43: 0 | I43: 211 | J43: Kayamandi1 | K43: =VLOOKUP(I43,[1]Kayamandi2!$A:$D,3,FALSE) -> -33.918405 | L43: =VLOOKUP(I43,[1]Kayamandi2!$A:$D,4,FALSE) -> 18.847373 | M43: =VLOOKUP(I43,'col requests'!E$83:G$92,3,FALSE) -> 1.6413258 | N43: =VLOOKUP(I43,'col requests'!H$83:I$92,2,FALSE) -> #N/A
A44: 0 | B44: 162 | C44: Cloetesville | D44: =VLOOKUP($B44,[1]Cloetesville!$A:$D,3,FALSE) -> -33.907594 | E44: =VLOOKUP($B44,[1]Cloetesville!$A:$D,4,FALSE) -> 18.858841 | F44: =VLOOKUP(B44,'col requests'!E$73:G$82,3,FALSE) -> 1.3962597 | H44: 0 | I44: 208 | J44: Kayamandi1 | K44: =VLOOKUP(I44,[1]Kayamandi2!$A:$D,3,FALSE) -> -33.913794 | L44: =VLOOKUP(I44,[1]Kayamandi2!$A:$D,4,FALSE) -> 18.845155 | M44: =VLOOKUP(I44,'col requests'!E$83:G$92,3,FALSE) -> 1.3811129 | N44: =VLOOKUP(I44,'col requests'!H$83:I$92,2,FALSE) -> #N/A
A45: 0 | B45: 160 | C45: Cloetesville | D45: =VLOOKUP($B45,[1]Cloetesville!$A:$D,3,FALSE) -> -33.910968 | E45: =VLOOKUP($B45,[1]Cloetesville!$A:$D,4,FALSE) -> 18.856746 | F45: =VLOOKUP(B45,'col requests'!E$73:G$82,3,FALSE) -> 1.3811129 | H45: 0 | I45: 212 | J45: Kayamandi1 | K45: =VLOOKUP(I45,[1]Kayamandi2!$A:$D,3,FALSE) -> -33.912735 | L45: =VLOOKUP(I45,[1]Kayamandi2!$A:$D,4,FALSE) -> 18.84515 | M45: =VLOOKUP(I45,'col requests'!E$83:G$92,3,FALSE) -> 1.4713939 | N45: =VLOOKUP(I45,'col requests'!H$83:I$92,2,FALSE) -> #N/A
...

Sheet optimalRoutes rawdata
